File: TiO2_reduction.vms
VAMAS Surface Chemical Analysis Standard Data Transfer Format 1988 May 4
Not Specified
Not Specified
Not Specified
Not Specified
285
Casa Info Follows CasaXPS Version 2.3.24rev1.1H
0
SourceAnalyserAngle: Not Specified
CasaRowLabel:O2, 1E-6 mbar O2, after 5min sputter
CasaRowLabel:O2, 1E-6 mbar O2, after 5min sputter
CasaRowLabel:O2, 1E-6 mbar O2, after 5min sputter
CasaRowLabel:O2, 1E-6 mbar O2, after 5min sputter
CasaRowLabel:O2, 1E-6 mbar O2, after 5min sputter
CasaRowLabel:O2, 1E-6 mbar O2, after 5min sputter
CasaRowLabel:O2, 1E-6 mbar O2, after 5min sputter
CasaRowLabel:O2, 1E-6 mbar O2, after 5min sputter
CasaRowLabel:O2, 1E-6 mbar O2, after 5min sputter
CasaRowLabel:O2, 1E-6 mbar O2, after 5min sputter
CasaRowLabel:O2, 1E-6 mbar O2, after 5min sputter
CasaRowLabel:800K, 1E-6 mbar O2, after 5min sputter
CasaRowLabel:800K, 1E-6 mbar O2, after 5min sputter
CasaRowLabel:800K, 1E-6 mbar O2, after 5min sputter
CasaRowLabel:800K, 1E-6 mbar O2, after 5min sputter
CasaRowLabel:800K, 1E-6 mbar O2, after 5min sputter
CasaRowLabel:800K, 1E-6 mbar O2, after 5min sputter
CasaRowLabel:800K, 1E-6 mbar O2, after 5min sputter
CasaRowLabel:800K, 1E-6 mbar O2, after 5min sputter
CasaRowLabel:800K, 1E-6 mbar O2, after 5min sputter
CasaRowLabel:800K, 1E-6 mbar O2, after 5min sputter
CasaRowLabel:800K, 1E-6 mbar O2, after 5min sputter
CasaRowLabel:800K, 1E-6 mbar O2, after 5min sputter
CasaRowLabel:800K, 1E-6 mbar O2, after 5min sputter
CasaRowLabel:800K, 1E-6 mbar O2, after 5min sputter
CasaRowLabel:800K, 1E-6 mbar O2, after 5min sputter
CasaRowLabel:800K, 1E-6 mbar O2, after 5min sputter
CasaRowLabel:800K, 1E-6 mbar O2, after 5min sputter
CasaRowLabel:800K, 1E-6 mbar O2, after 5min sputter
CasaRowLabel:800K, 1E-6 mbar O2, after 5min sputter
CasaRowLabel:800K, 1E-6 mbar O2, after 5min sputter
CasaRowLabel:800K, 1E-6 mbar O2, after 5min sputter
CasaRowLabel:800K, 1E-6 mbar O2, after 5min sputter
CasaRowLabel:800K, 1E-6 mbar O2, after 5min sputter
CasaRowLabel:800K, 1E-6 mbar O2, after 5min sputter
CasaRowLabel:800K, 1E-6 mbar O2, after 5min sputter
CasaRowLabel:800K, 1E-6 mbar O2, after 5min sputter
CasaRowLabel:800K, 1E-6 mbar O2, after 5min sputter
CasaRowLabel:800K, 1E-6 mbar O2, after 5min sputter
CasaRowLabel:800K, 1E-6 mbar O2, after 5min sputter
CasaRowLabel:800K, 1E-6 mbar O2, after 5min sputter
CasaRowLabel:800K, 1E-6 mbar O2, after 5min sputter
CasaRowLabel:800K, 1E-6 mbar O2, after 5min sputter
CasaRowLabel:800K, 1E-6 mbar O2, after 5min sputter
CasaRowLabel:800K, 1E-6 mbar O2, after 5min sputter
CasaRowLabel:800K, 1E-6 mbar O2, after 5min sputter
CasaRowLabel:800K, vacuum, after oxidation
CasaRowLabel:800K, vacuum, after oxidation
CasaRowLabel:800K, vacuum, after oxidation
CasaRowLabel:800K, vacuum, after oxidation
CasaRowLabel:800K, vacuum, after oxidation
CasaRowLabel:800K, vacuum, after oxidation
CasaRowLabel:800K, vacuum, after oxidation
CasaRowLabel:800K, vacuum, after oxidation
CasaRowLabel:800K, vacuum, after oxidation
CasaRowLabel:800K, vacuum, after oxidation
CasaRowLabel:800K, vacuum, after oxidation
CasaRowLabel:800K, vacuum, after oxidation
CasaRowLabel:800K, vacuum, after oxidation
CasaRowLabel:800K, vacuum, after oxidation
CasaRowLabel:800K, vacuum, after oxidation
CasaRowLabel:800K, vacuum, after oxidation
CasaRowLabel:800K, vacuum, after oxidation
CasaRowLabel:800K, vacuum, after oxidation
CasaRowLabel:800K, vacuum, after oxidation
CasaRowLabel:800K, vacuum, after oxidation
CasaRowLabel:800K, vacuum, after oxidation
CasaRowLabel:800K, vacuum, after oxidation
CasaRowLabel:800K, vacuum, after oxidation
CasaRowLabel:800K, vacuum, after oxidation
CasaRowLabel:800K, vacuum, after oxidation
CasaRowLabel:800K, vacuum, after oxidation
CasaRowLabel:800K, vacuum, after oxidation
CasaRowLabel:800K, vacuum, after oxidation
CasaRowLabel:800K, vacuum, after oxidation
CasaRowLabel:800K, vacuum, after oxidation
CasaRowLabel:800K, vacuum, after oxidation
CasaRowLabel:800K, vacuum, after oxidation
CasaRowLabel:800K, vacuum, after oxidation
CasaRowLabel:800K, vacuum, after oxidation
CasaRowLabel:800K, vacuum, after oxidation
CasaRowLabel:800K, vacuum, after oxidation
CasaRowLabel:800K, vacuum, after oxidation
CasaRowLabel:800K, vacuum, after oxidation
CasaRowLabel:800K, vacuum, after oxidation
CasaRowLabel:800K, vacuum, after oxidation
CasaRowLabel:800K, vacuum, after oxidation
CasaRowLabel:800K, vacuum, after oxidation
CasaRowLabel:800K, vacuum, after oxidation
CasaRowLabel:800K, vacuum, after oxidation
CasaRowLabel:800K, vacuum, after oxidation
CasaRowLabel:800K, vacuum, after oxidation
CasaRowLabel:800K, vacuum, after oxidation
CasaRowLabel:800K, vacuum, after oxidation
CasaRowLabel:800K, vacuum, after oxidation
CasaRowLabel:800K, vacuum, after oxidation
CasaRowLabel:800K, vacuum, after oxidation
CasaRowLabel:800K, vacuum, after oxidation
CasaRowLabel:800K, vacuum, after oxidation
CasaRowLabel:800K, vacuum, after oxidation
CasaRowLabel:800K, vacuum, after oxidation
CasaRowLabel:800K, vacuum, after oxidation
CasaRowLabel:800K, vacuum, after oxidation
CasaRowLabel:800K, vacuum, after oxidation
CasaRowLabel:800K, vacuum, after oxidation
CasaRowLabel:800K, vacuum, after oxidation
CasaRowLabel:800K, vacuum, after oxidation
CasaRowLabel:800K, vacuum, after oxidation
CasaRowLabel:800K, vacuum, after oxidation
CasaRowLabel:800K, vacuum, after oxidation
CasaRowLabel:800K, vacuum, after oxidation
CasaRowLabel:800K, vacuum, after oxidation
CasaRowLabel:800K, vacuum, after oxidation
CasaRowLabel:800K, vacuum, after oxidation
CasaRowLabel:800K, vacuum, after oxidation
CasaRowLabel:800K, vacuum, after oxidation
CasaRowLabel:800K, vacuum, after oxidation
CasaRowLabel:800K, vacuum, after oxidation
CasaRowLabel:800K, vacuum, after oxidation
CasaRowLabel:800K, vacuum, after oxidation
CasaRowLabel:800K, vacuum, after oxidation
CasaRowLabel:800K, vacuum, after oxidation
CasaRowLabel:800K, vacuum, after oxidation
CasaRowLabel:800K, vacuum, after oxidation
CasaRowLabel:800K, vacuum, after oxidation
CasaRowLabel:800K, vacuum, after oxidation
CasaRowLabel:800K, vacuum, after oxidation
CasaRowLabel:800K, vacuum, after oxidation
CasaRowLabel:800K, vacuum, after oxidation
CasaRowLabel:800K, vacuum, after oxidation
CasaRowLabel:800K, vacuum, after oxidation
CasaRowLabel:800K, vacuum, after oxidation
CasaRowLabel:800K, vacuum, after oxidation
CasaRowLabel:800K, vacuum, after oxidation
CasaRowLabel:800K, vacuum, after oxidation
CasaRowLabel:800K, vacuum, after oxidation
CasaRowLabel:800K, vacuum, after oxidation
CasaRowLabel:800K, vacuum, after oxidation
CasaRowLabel:800K, vacuum, after oxidation
CasaRowLabel:800K, vacuum, after oxidation
CasaRowLabel:800K, vacuum, after oxidation
CasaRowLabel:800K, vacuum, after oxidation
CasaRowLabel:800K, vacuum, after oxidation
CasaRowLabel:800K, vacuum, after oxidation
CasaRowLabel:800K, vacuum, after oxidation
CasaRowLabel:800K, vacuum, after oxidation
CasaRowLabel:800K, vacuum, after oxidation
CasaRowLabel:800K, vacuum, after oxidation
CasaRowLabel:800K, vacuum, after oxidation
CasaRowLabel:800K, vacuum, after oxidation
CasaRowLabel:800K, vacuum, after oxidation
CasaRowLabel:800K, vacuum, after oxidation
CasaRowLabel:800K, vacuum, after oxidation
CasaRowLabel:800K, vacuum, after oxidation
CasaRowLabel:800K, vacuum, after oxidation
CasaRowLabel:800K, vacuum, after oxidation
CasaRowLabel:800K, vacuum, after oxidation
CasaRowLabel:800K, vacuum, after oxidation
CasaRowLabel:800K, vacuum, after oxidation
CasaRowLabel:800K, vacuum, after oxidation
CasaRowLabel:800K, vacuum, after oxidation
CasaRowLabel:800K, vacuum, after oxidation
CasaRowLabel:800K, vacuum, after oxidation
CasaRowLabel:800K, vacuum, after oxidation
CasaRowLabel:800K, vacuum, after oxidation
CasaRowLabel:800K, vacuum, after oxidation
CasaRowLabel:800K, vacuum, after oxidation
CasaRowLabel:800K, vacuum, after oxidation
CasaRowLabel:800K, vacuum, after oxidation
CasaRowLabel:800K, vacuum, after oxidation
CasaRowLabel:800K, vacuum, after oxidation
CasaRowLabel:800K, vacuum, after oxidation
CasaRowLabel:800K, vacuum, after oxidation
CasaRowLabel:800K, vacuum, after oxidation
CasaRowLabel:800K, vacuum, after oxidation
CasaRowLabel:800K, vacuum, after oxidation
CasaRowLabel:800K, vacuum, after oxidation
CasaRowLabel:800K, vacuum, after oxidation
CasaRowLabel:800K, vacuum, after oxidation
CasaRowLabel:800K, vacuum, after oxidation
CasaRowLabel:800K, vacuum, after oxidation
CasaRowLabel:800K, vacuum, after oxidation
CasaRowLabel:800K, vacuum, after oxidation
CasaRowLabel:800K, vacuum, after oxidation
CasaRowLabel:800K, vacuum, after oxidation
CasaRowLabel:800K, vacuum, after oxidation
CasaRowLabel:800K, vacuum, after oxidation
CasaRowLabel:800K, vacuum, after oxidation
CasaRowLabel:800K, vacuum, after oxidation
CasaRowLabel:800K, vacuum, after oxidation
CasaRowLabel:800K, vacuum, after oxidation
CasaRowLabel:800K, vacuum, after oxidation
CasaRowLabel:800K, vacuum, after oxidation
CasaRowLabel:800K, vacuum, after oxidation
CasaRowLabel:800K, vacuum, after oxidation
CasaRowLabel:800K, vacuum, after oxidation
CasaRowLabel:900K, vacuum, after oxidation
CasaRowLabel:900K, vacuum, after oxidation
CasaRowLabel:900K, vacuum, after oxidation
CasaRowLabel:900K, vacuum, after oxidation
CasaRowLabel:900K, vacuum, after oxidation
CasaRowLabel:900K, vacuum, after oxidation
CasaRowLabel:900K, vacuum, after oxidation
CasaRowLabel:900K, vacuum, after oxidation
CasaRowLabel:900K, vacuum, after oxidation
CasaRowLabel:900K, vacuum, after oxidation
CasaRowLabel:900K, vacuum, after oxidation
CasaRowLabel:900K, vacuum, after oxidation
CasaRowLabel:900K, vacuum, after oxidation
CasaRowLabel:900K, vacuum, after oxidation
CasaRowLabel:900K, vacuum, after oxidation
CasaRowLabel:800K, O2, 3E-9 mbar O2, after reduction
CasaRowLabel:800K, O2, 3E-9 mbar O2, after reduction
CasaRowLabel:800K, O2, 3E-9 mbar O2, after reduction
CasaRowLabel:800K, O2, 3E-9 mbar O2, after reduction
CasaRowLabel:800K, O2, 3E-9 mbar O2, after reduction
CasaRowLabel:800K, O2, 3E-9 mbar O2, after reduction
CasaRowLabel:800K, O2, 3E-9 mbar O2, after reduction
CasaRowLabel:800K, O2, 3E-9 mbar O2, after reduction
CasaRowLabel:800K, O2, 3E-9 mbar O2, after reduction
CasaRowLabel:800K, O2, 3E-9 mbar O2, after reduction
CasaRowLabel:800K, O2, 3E-9 mbar O2, after reduction
CasaRowLabel:800K, O2, 3E-9 mbar O2, after reduction
CasaRowLabel:800K, O2, 3E-9 mbar O2, after reduction
CasaRowLabel:800K, O2, 1E-8 mbar O2, after reduction
CasaRowLabel:800K, O2, 1E-8 mbar O2, after reduction
CasaRowLabel:800K, O2, 1E-8 mbar O2, after reduction
CasaRowLabel:800K, O2, 1E-8 mbar O2, after reduction
CasaRowLabel:800K, O2, 1E-8 mbar O2, after reduction
CasaRowLabel:800K, O2, 1E-8 mbar O2, after reduction
CasaRowLabel:800K, O2, 3E-8 mbar O2, after reduction
CasaRowLabel:800K, O2, 3E-8 mbar O2, after reduction
CasaRowLabel:800K, O2, 3E-8 mbar O2, after reduction
CasaRowLabel:800K, O2, 3E-8 mbar O2, after reduction
CasaRowLabel:800K, O2, 3E-8 mbar O2, after reduction
CasaRowLabel:800K, O2, 3E-8 mbar O2, after reduction
CasaRowLabel:800K, O2, 3E-8 mbar O2, after reduction
CasaRowLabel:800K, O2, 3E-8 mbar O2, after reduction
CasaRowLabel:800K, O2, 3E-8 mbar O2, after reduction
CasaRowLabel:800K, O2, 3E-8 mbar O2, after reduction
CasaRowLabel:800K, O2, 3E-8 mbar O2, after reduction
CasaRowLabel:800K, O2, 3E-8 mbar O2, after reduction
CasaRowLabel:800K, O2, 3E-8 mbar O2, after reduction
CasaRowLabel:800K, O2, 3E-8 mbar O2, after reduction
CasaRowLabel:800K, O2, 3E-8 mbar O2, after reduction
CasaRowLabel:800K, O2, 3E-8 mbar O2, after reduction
CasaRowLabel:800K, O2, 3E-8 mbar O2, after reduction
CasaRowLabel:800K, O2, 3E-8 mbar O2, after reduction
CasaRowLabel:800K, O2, 3E-8 mbar O2, after reduction
CasaRowLabel:800K, O2, 3E-8 mbar O2, after reduction
CasaRowLabel:800K, O2, 7E-8 to 2E-7 mbar O2, after reduction
CasaRowLabel:800K, O2, 7E-8 to 2E-7 mbar O2, after reduction
CasaRowLabel:800K, O2, 7E-8 to 2E-7 mbar O2, after reduction
CasaRowLabel:800K, O2, 5E-7 mbar O2, after reduction
CasaRowLabel:800K, O2, 5E-7 mbar O2, after reduction
CasaRowLabel:800K, O2, 5E-7 mbar O2, after reduction
CasaRowLabel:800K, O2, 5E-7 mbar O2, after reduction
CasaRowLabel:800K, O2, 5E-7 mbar O2, after reduction
CasaRowLabel:800K, O2, 5E-7 mbar O2, after reduction
CasaRowLabel:800K, O2, 5E-7 mbar O2, after reduction
CasaRowLabel:800K, O2, 5E-7 mbar O2, after reduction
CasaRowLabel:800K, O2, 5E-7 mbar O2, after reduction
CasaRowLabel:800K, O2, 5E-7 mbar O2, after reduction
CasaRowLabel:800K, O2, 5E-7 mbar O2, after reduction
CasaRowLabel:800K, O2, 5E-7 mbar O2, after reduction
CasaRowLabel:800K, O2, 5E-7 mbar O2, after reduction
CasaRowLabel:800K, O2, 5E-7 mbar O2, after reduction
CasaRowLabel:800K, O2, 5E-7 mbar O2, after reduction
CasaRowLabel:800K, O2, 5E-7 mbar O2, after reduction
CasaRowLabel:800K, O2, 5E-7 mbar O2, after reduction
CasaRowLabel:800K, O2, 5E-7 mbar O2, after reduction
CasaRowLabel:800K, O2, 5E-7 mbar O2, after reduction
CasaRowLabel:800K, O2, 5E-7 mbar O2, after reduction
CasaRowLabel:800K, O2, 5E-7 mbar O2, after reduction
CasaRowLabel:800K, O2, 5E-7 mbar O2, after reduction
CasaRowLabel:800K, O2, 5E-7 mbar O2, after reduction
CasaRowLabel:800K, O2, 5E-7 mbar O2, after reduction
CasaRowLabel:800K, O2, 5E-7 mbar O2, after reduction
CasaRowLabel:800K, O2, 5E-7 mbar O2, after reduction
CasaRowLabel:800K, O2, 5E-7 mbar O2, after reduction
CasaRowLabel:800K, O2, 5E-7 mbar O2, after reduction
CasaRowLabel:800K, O2, 5E-7 mbar O2, after reduction
NORM
REGULAR
1
1
Exp Variable
d
0
0
0
0
282
Ti 2p
O2, 1E-6 mbar O2, after 5min sputter
2030
2019
3
3
56
26
0
10
Casa Info Follows
0
0
0
0
none
Group: none
Analyzer Lens: none
Analyzer Slit: none
Scan Mode: none
XPS
0
XR 50
1486.61
0
0
0
56.5
180
FAT
20
1
4.2488
0
0
0
0
0
Ti
2p
-1
binding energy
eV
471
0.05
2
counts
d
Transmission
d
pulse counting
0.1
1
0
0
0
0
2
ESCAPE DEPTH TYPE
d
0
MFP Exponent
d
0
1002
64.0476
6342.49
1
1
134.366
1
128.194
1
116.555
1
113.531
1
115.103
1
107.921
1
106.512
1
103.57
1
98.7206
1
113.667
1
116.049
1
119.872
1
100.823
1
100.029
1
104.259
1
103.279
1
93.8098
1
95.1051
1
93.5519
1
96.984
1
105.352
1
106.158
1
98.2349
1
100.8
1
109.676
1
102.974
1
102.573
1
104.274
1
91.8203
1
101.562
1
79.5221
1
96.2494
1
97.0436
1
95.4445
1
99.0644
1
101.144
1
99.9646
1
94.0944
1
74.4875
1
92.7394
1
90.4082
1
86.3737
1
89.1306
1
83.5747
1
94.1558
1
100.688
1
84.7494
1
88.1853
1
81.1273
1
80.7895
1
73.7501
1
87.2692
1
90.9079
1
99.1295
1
101.263
1
86.7831
1
94.809
1
90.7178
1
84.1744
1
91.3704
1
72.4646
1
84.474
1
89.6853
1
86.9042
1
94.1402
1
86.7209
1
86.0941
1
92.0126
1
88.5598
1
107.527
1
100.797
1
88.6416
1
80.8907
1
74.1438
1
93.0406
1
96.0318
1
96.371
1
90.4975
1
101.297
1
95.9192
1
114.334
1
101.081
1
91.2029
1
107.867
1
116.74
1
93.7067
1
106.235
1
114.256
1
106.926
1
113.009
1
102.764
1
106.711
1
120.406
1
111.073
1
126.525
1
141.115
1
124.447
1
122.288
1
147.475
1
143.892
1
147.895
1
163.074
1
150.67
1
158.578
1
160.985
1
152.798
1
182.737
1
184.318
1
197.803
1
210.006
1
199.699
1
192.301
1
210.779
1
210.193
1
209.148
1
225.884
1
230.396
1
246.568
1
254.395
1
233.133
1
229.798
1
249.174
1
237.306
1
251.332
1
226.893
1
219.839
1
244.992
1
243.076
1
249.811
1
248.894
1
249.731
1
230.877
1
223.965
1
211.552
1
228.516
1
240.675
1
225.517
1
223.268
1
208.234
1
208.184
1
202.916
1
202.06
1
200.185
1
202.939
1
160.234
1
157.244
1
162.763
1
160.156
1
173.932
1
144.312
1
132.439
1
142.371
1
142.95
1
139.442
1
136.213
1
127.385
1
131.444
1
132.986
1
130.308
1
108.691
1
121.787
1
116.239
1
118.978
1
111.231
1
112.501
1
94.707
1
87.8468
1
101.615
1
109.831
1
97.0174
1
90.1948
1
98.6037
1
89.863
1
90.6464
1
91.6118
1
88.5038
1
95.3728
1
92.6875
1
87.707
1
90.0899
1
87.5699
1
84.748
1
85.5639
1
87.9732
1
96.0471
1
79.2704
1
88.983
1
107.395
1
90.5406
1
89.1639
1
92.0047
1
98.926
1
94.7013
1
73.9792
1
83.2338
1
97.024
1
98.9485
1
91.5009
1
87.9381
1
89.9317
1
87.5678
1
89.7232
1
106.21
1
89.1571
1
94.9757
1
99.2711
1
99.6522
1
98.291
1
99.2716
1
115.431
1
115.886
1
115.939
1
128.918
1
143.892
1
139.092
1
143.258
1
149.242
1
145.869
1
137.641
1
164.762
1
182.369
1
186.614
1
217.049
1
235.406
1
245.932
1
252.665
1
273.126
1
300.264
1
338.092
1
379.449
1
399.577
1
402.691
1
412.638
1
461.358
1
525.216
1
568.613
1
585.307
1
558.323
1
579.578
1
593.545
1
604.788
1
616.207
1
634.249
1
625.262
1
592.833
1
597.116
1
560.301
1
570.344
1
527.692
1
496.104
1
454.065
1
434.067
1
401.032
1
362.512
1
333.997
1
284.803
1
257.732
1
223.814
1
222.55
1
200.313
1
163.812
1
155.317
1
134.638
1
127.108
1
124.955
1
116.073
1
107.748
1
99.5357
1
77.662
1
70.8546
1
79.119
1
79.1109
1
85.2197
1
68.1431
1
55.67
1
62.5699
1
57.2467
1
43.8162
1
50.8813
1
54.7123
1
54.0651
1
58.1206
1
53.1216
1
60.5351
1
58.4746
1
51.3876
1
35.1015
1
36.9394
1
38.4766
1
43.3703
1
32.5952
1
33.9706
1
25.3738
1
28.7657
1
21.4298
1
21.9878
1
25.664
1
22.936
1
24.354
1
28.1859
1
24.8124
1
19.4197
1
17.5048
1
12.5473
1
22.9074
1
20.6641
1
20.7252
1
26.7212
1
19.0288
1
11.6591
1
15.3864
1
19.1592
1
15.9584
1
25.9729
1
21.1641
1
17.344
1
21.9817
1
19.3218
1
17.0914
1
12.019
1
10.0282
1
12.4697
1
18.4799
1
20.9454
1
16.1924
1
19.0495
1
15.2367
1
15.2356
1
13.9607
1
15.2851
1
16.3187
1
11.9174
1
15.4025
1
15.7743
1
18.8847
1
13.6262
1
14.766
1
18.5769
1
17.9996
1
14.6698
1
16.708
1
9.03356
1
12.3347
1
13.2995
1
15.5818
1
17.0236
1
12.9025
1
17.8562
1
18.5888
1
20.9062
1
16.5722
1
17.5435
1
9.0288
1
11.5554
1
8.78732
1
11.1841
1
18.8862
1
17.2361
1
14.4179
1
17.8835
1
15.8746
1
12.0388
1
17.5924
1
11.8258
1
15.8848
1
15.6234
1
15.373
1
16.0398
1
19.9596
1
13.1855
1
20.3988
1
12.1275
1
11.4101
1
7.4148
1
11.7966
1
12.8338
1
13.4042
1
13.8387
1
13.0263
1
12.8419
1
18.877
1
15.6678
1
10.5537
1
15.3738
1
9.19968
1
7.14224
1
10.773
1
18.2502
1
9.82596
1
12.776
1
14.0573
1
16.8354
1
13.4199
1
9.97708
1
14.835
1
9.41052
1
12.8496
1
15.614
1
12.1927
1
7.0484
1
10.5417
1
14.1924
1
15.9653
1
16.3644
1
13.6646
1
16.3878
1
12.5342
1
10.8123
1
9.56968
1
12.4241
1
17.0603
1
14.2561
1
16.3184
1
18.4603
1
11.1716
1
10.2778
1
15.4937
1
14.2392
1
20.3069
1
11.5643
1
11.4557
1
12.4754
1
15.9001
1
18.9792
1
12.4168
1
11.3694
1
14.434
1
9.84792
1
13.7813
1
7.31928
1
11.2664
1
15.3309
1
15.5383
1
10.7146
1
16.2212
1
10.2584
1
8.72724
1
7.84776
1
14.4152
1
14.3583
1
15.9839
1
12.8013
1
9.396
1
8.4168
1
11.4072
1
12.2391
1
8.74008
1
10.9614
1
13.2361
1
10.3068
1
8.65068
1
10.5936
1
16.4036
1
12.386
1
13.8254
1
13.9992
1
14.2751
1
7.95828
1
9.46368
1
14.2343
1
8.25692
1
12.5204
1
14.28
1
16.456
1
13.5718
1
12.287
1
10.6808
1
10.4335
1
12.8428
1
15.1976
1
9.2482
1
8.73148
1
15.9926
1
15.4826
1
12.2666
1
9.90908
1
14.8266
1
12.1496
1
8.6904
1
12.2068
1
12.7404
1
11.6896
1
13.5665
1
14.2434
1
17.8098
1
12.0066
1
9.43404
1
12.0553
1
11.3056
1
11.042
1
13.0849
1
11.2195
1
9.66164
1
6.40476
1
11.1696
1
16.1818
1
16.5315
1
10.1579
1
11.416
1
19.0718
1
15.6861
1
Ti 2p
O2, 1E-6 mbar O2, after 5min sputter
2030
2019
3
3
58
48
0
10
Casa Info Follows
0
0
0
0
none
Group: none
Analyzer Lens: none
Analyzer Slit: none
Scan Mode: none
XPS
0
XR 50
1486.61
0
0
0
56.5
180
FAT
20
1
4.2488
0
0
0
0
0
Ti
2p
-1
binding energy
eV
471
0.05
2
counts
d
Transmission
d
pulse counting
0.1
1
0
0
0
0
2
ESCAPE DEPTH TYPE
d
0
MFP Exponent
d
0
1002
67.6388
6394.12
1
1
114.455
1
121.535
1
111.986
1
129.41
1
114.878
1
113.764
1
114.204
1
111.03
1
116.266
1
112.312
1
103.65
1
102.916
1
110.946
1
98.1812
1
88.0577
1
109.894
1
100.73
1
105.694
1
93.315
1
105.101
1
108.865
1
85.0084
1
101.689
1
104.931
1
114.884
1
86.5251
1
90.5484
1
84.3284
1
91.7291
1
92.8349
1
84.0306
1
88.6131
1
93.2221
1
92.9122
1
98.9997
1
96.6761
1
97.1888
1
102.572
1
100.064
1
96.4645
1
90.4125
1
90.1477
1
99.0466
1
96.3958
1
96.2888
1
79.9318
1
84.409
1
92.2588
1
94.1507
1
101.307
1
91.4886
1
78.448
1
94.8086
1
95.5062
1
81.6047
1
79.9632
1
90.7266
1
76.6614
1
83.8962
1
81.9871
1
83.1232
1
82.7668
1
82.5958
1
89.0323
1
91.9436
1
85.8461
1
89.2864
1
84.041
1
83.0044
1
79.6036
1
87.0395
1
91.4752
1
91.394
1
99.5288
1
87.7211
1
93.0016
1
95.0946
1
99.1648
1
106.621
1
95.2097
1
89.6032
1
104.073
1
114.05
1
99.7038
1
92.9698
1
111.036
1
108.106
1
102.52
1
104.519
1
106.009
1
114.672
1
107.981
1
132.927
1
122.113
1
105.146
1
130.346
1
132.729
1
122.763
1
115.15
1
127.754
1
144.698
1
144.169
1
155.481
1
160.238
1
163.09
1
155.4
1
177.714
1
182.531
1
186.688
1
169.785
1
201.022
1
192.625
1
189.04
1
207.82
1
230.752
1
221.292
1
215.106
1
227.954
1
228.802
1
244.469
1
236.585
1
255.156
1
250.56
1
278.624
1
278.872
1
250.63
1
245.788
1
259.147
1
209.363
1
226.938
1
241.498
1
232.052
1
239.784
1
222.643
1
247.328
1
216.961
1
220.875
1
221.244
1
227.084
1
194.889
1
202.994
1
235.15
1
210.416
1
202.376
1
191.351
1
187.126
1
201.474
1
174.807
1
172.72
1
170.771
1
152.409
1
150.703
1
151.869
1
145.389
1
141.278
1
133.881
1
129.506
1
135.806
1
139.524
1
111.711
1
111.848
1
112.97
1
106.137
1
104.982
1
124.377
1
114.826
1
101.467
1
101.169
1
94.5188
1
103.624
1
103.484
1
96.8408
1
102.385
1
98.3593
1
92.9836
1
99.5577
1
89.6713
1
98.485
1
98.4531
1
86.8234
1
88.0597
1
88.0806
1
84.4671
1
92.5334
1
74.2765
1
72.9755
1
90.0296
1
96.6112
1
85.9774
1
82.6157
1
94.8826
1
79.8121
1
88.4292
1
99.5235
1
88.6616
1
86.6173
1
102.939
1
99.9672
1
98.3136
1
89.8551
1
102.504
1
102.952
1
98.681
1
100.485
1
105.493
1
102.167
1
104.782
1
100.109
1
111.64
1
111.378
1
116.526
1
126.532
1
134.615
1
116.562
1
128.662
1
122.48
1
136.198
1
124.13
1
154.576
1
151.021
1
180.432
1
198.876
1
203.283
1
204.075
1
253.553
1
270.06
1
267.545
1
331.684
1
369.1
1
380.444
1
377.883
1
421.718
1
469.393
1
516.774
1
510.144
1
569.604
1
540.519
1
594.267
1
594.511
1
578.357
1
584.058
1
633.875
1
611.365
1
626.537
1
639.412
1
637.28
1
569.822
1
554.648
1
563.087
1
514.264
1
457.741
1
422.027
1
392.401
1
324.594
1
326.242
1
312.29
1
264.333
1
224.986
1
216.791
1
202.524
1
178.078
1
163.779
1
154.864
1
138.93
1
120.304
1
92.182
1
96.9739
1
89.1705
1
92.1002
1
99.9228
1
86.4687
1
71.4362
1
58.7367
1
61.9244
1
62.833
1
61.5793
1
64.2404
1
57.2773
1
61.99
1
64.7518
1
46.2227
1
50.7596
1
49.9991
1
55.4999
1
47.029
1
48.0805
1
33.1653
1
35.54
1
46.7645
1
42.5131
1
38.3044
1
35.6947
1
32.2706
1
29.0282
1
24.7156
1
27.8047
1
28.0902
1
27.1096
1
20.8042
1
16.9636
1
23.3549
1
26.7053
1
24.4078
1
18.654
1
23.9763
1
14.7781
1
15.0576
1
17.446
1
23.4179
1
19.6964
1
17.6368
1
21.0384
1
26.2823
1
22.6955
1
25.37
1
18.631
1
19.3722
1
18.2617
1
12.98
1
17.8745
1
18.7952
1
24.0732
1
17.8077
1
23.134
1
14.4004
1
16.7802
1
13.5386
1
14.1148
1
13.5866
1
14.1052
1
8.5456
1
14.4944
1
14.0402
1
17.3288
1
16.2192
1
15.3931
1
9.92444
1
13.3401
1
12.5098
1
10.8279
1
10.0729
1
14.755
1
20.6136
1
14.5893
1
10.3758
1
15.7645
1
19.1479
1
10.813
1
14.9199
1
16.1382
1
14.9306
1
8.63292
1
10.186
1
10.2689
1
13.7343
1
19.2522
1
17.6758
1
21.1208
1
10.6954
1
12.5728
1
18.244
1
21.1117
1
19.161
1
13.1036
1
21.1807
1
16.0678
1
12.2516
1
13.4914
1
18.2111
1
19.7106
1
17.7531
1
15.1977
1
12.1618
1
16.225
1
8.10348
1
6.76388
1
16.4974
1
22.3944
1
14.4836
1
12.9616
1
17.2465
1
18.1228
1
12.5568
1
12.4508
1
11.5354
1
10.8994
1
14.606
1
17.1026
1
10.3898
1
10.4164
1
10.9685
1
10.3652
1
10.1644
1
10.0941
1
17.0265
1
13.8289
1
16.8622
1
13.0991
1
9.5464
1
13.0225
1
13.8126
1
16.5538
1
11.1777
1
12.2604
1
16.4508
1
11.3703
1
11.2893
1
10.7752
1
10.9469
1
13.5572
1
13.3639
1
11.9258
1
13.6147
1
11.9412
1
9.58392
1
7.11232
1
18.2226
1
12.8496
1
9.86032
1
11.2776
1
14.139
1
13.1313
1
16.1407
1
13.7389
1
17.9765
1
11.5729
1
23.6363
1
18.5408
1
16.146
1
15.1278
1
12.6
1
11.766
1
12.7499
1
11.4285
1
11.508
1
11.875
1
9.2514
1
21.0222
1
15.6577
1
12.0584
1
12.538
1
10.4776
1
12.3512
1
13.9247
1
13.6308
1
13.4603
1
16.1364
1
10.9514
1
12.1539
1
11.4496
1
10.8026
1
10.0772
1
19.5188
1
19.0237
1
7.52184
1
10.0295
1
11.7404
1
11.5904
1
9.5154
1
7.22304
1
12.4483
1
14.4184
1
17.6754
1
16.0088
1
15.5742
1
15.995
1
18.9655
1
11.6942
1
14.7171
1
12.5656
1
13.3361
1
14.8276
1
11.6419
1
14.8806
1
12.0484
1
13.8239
1
12.183
1
12.2771
1
13.1505
1
12.0656
1
13.7537
1
9.09964
1
10.9943
1
12.311
1
13.2036
1
10.811
1
14.8692
1
17.4804
1
15.1038
1
11.8162
1
11.3397
1
14.2563
1
12.1724
1
11.7764
1
13.2904
1
14.9056
1
20.9484
1
15.8389
1
14.2656
1
7.40272
1
10.0308
1
Ti 2p
O2, 1E-6 mbar O2, after 5min sputter
2030
2019
3
4
1
10
0
10
Casa Info Follows
0
0
0
0
none
Group: none
Analyzer Lens: none
Analyzer Slit: none
Scan Mode: none
XPS
0
XR 50
1486.61
0
0
0
56.5
180
FAT
20
1
4.2488
0
0
0
0
0
Ti
2p
-1
binding energy
eV
471
0.05
2
counts
d
Transmission
d
pulse counting
0.1
1
0
0
0
0
2
ESCAPE DEPTH TYPE
d
0
MFP Exponent
d
0
1002
61.136
6495.56
1
1
119.975
1
120.563
1
119.24
1
106.104
1
109.35
1
117.088
1
100.891
1
91.1395
1
118.634
1
119.265
1
121.433
1
109.282
1
92.8823
1
118.955
1
101.776
1
112.536
1
113.386
1
121.955
1
110.537
1
116.259
1
110.134
1
86.787
1
90.6818
1
97.5694
1
116.799
1
114.716
1
98.0814
1
109.904
1
111.852
1
115.81
1
103.401
1
119.584
1
102.278
1
93.9447
1
92.7573
1
86.3546
1
87.685
1
96.0056
1
108.115
1
85.894
1
85.1156
1
98.7505
1
110.392
1
112.067
1
94.3828
1
94.5403
1
93.3904
1
81.5509
1
84.6874
1
83.6553
1
75.9197
1
84.7581
1
100.645
1
88.3128
1
99.9252
1
94.4565
1
73.2262
1
89.722
1
86.292
1
90.8626
1
102.157
1
89.6934
1
94.5002
1
89.562
1
85.3639
1
85.8822
1
99.9853
1
100.843
1
96.0207
1
102.326
1
86.484
1
91.8434
1
94.8484
1
86.958
1
97.43
1
98.6788
1
91.5099
1
76.6448
1
103.767
1
92.2896
1
94.7076
1
98.7448
1
94.4382
1
87.0198
1
120.005
1
103.266
1
101.043
1
103.067
1
96.2524
1
107.689
1
114.364
1
115.839
1
130.221
1
135.158
1
136.6
1
146.954
1
143.573
1
149.859
1
169.375
1
148.57
1
144.085
1
153.193
1
156.045
1
153.893
1
156.924
1
157.569
1
164.087
1
178.597
1
198.996
1
202.175
1
193.112
1
213.122
1
216.072
1
231.137
1
238.917
1
236.56
1
234.009
1
233.542
1
247.596
1
238.149
1
241.927
1
253.088
1
253.308
1
270.892
1
277.605
1
264.704
1
259.824
1
265.434
1
235.851
1
261.325
1
254.775
1
234.435
1
257.598
1
257.355
1
244.363
1
230.67
1
229.758
1
245.04
1
220.284
1
215.961
1
228.606
1
227.808
1
223.847
1
203.932
1
181.847
1
181.213
1
176.129
1
161.9
1
143.598
1
139.107
1
161.105
1
155.113
1
136.599
1
119.821
1
129.704
1
138.778
1
129.496
1
128.993
1
130.473
1
125.748
1
117.64
1
106.691
1
107.664
1
127.616
1
95.6927
1
101.91
1
98.7183
1
112.535
1
106.358
1
95.9154
1
92.6852
1
112.057
1
100.502
1
97.0482
1
90.0176
1
76.297
1
83.0544
1
96.2923
1
100.391
1
95.8236
1
77.7031
1
76.7933
1
90.0572
1
86.4443
1
98.8436
1
101.205
1
100.939
1
99.0383
1
99.2677
1
100.643
1
95.1363
1
90.8964
1
90.8804
1
89.5178
1
84.7986
1
94.6908
1
95.4799
1
90.68
1
83.3077
1
117.056
1
101.152
1
95.155
1
94.578
1
111.448
1
105.993
1
104.178
1
86.9446
1
114.189
1
113.669
1
108.661
1
97.0544
1
119.997
1
122.365
1
128.312
1
135.906
1
140.894
1
154.409
1
137.27
1
155.934
1
177.022
1
180.957
1
189.388
1
212.106
1
233.96
1
252.242
1
290.02
1
320.938
1
322.138
1
305.441
1
351.997
1
384.309
1
389.421
1
482.608
1
472.059
1
517.61
1
558.242
1
570.193
1
608.446
1
589.42
1
617.889
1
624.023
1
642.933
1
637.677
1
599.919
1
649.556
1
615.909
1
608.502
1
578.82
1
538.627
1
497.419
1
492.15
1
449.062
1
387.521
1
392.259
1
363.023
1
328.503
1
263.031
1
273.574
1
222.059
1
176.524
1
183.005
1
174.54
1
138.737
1
137.318
1
122.667
1
101.641
1
110.632
1
105.499
1
89.6056
1
76.7575
1
74.2763
1
78.2366
1
77.6732
1
66.6957
1
65.2619
1
58.5289
1
57.1142
1
68.2788
1
59.3546
1
47.2715
1
58.0714
1
57.5497
1
55.5307
1
62.1584
1
57.2624
1
48.4228
1
58.3848
1
52.8976
1
39.9506
1
38.0786
1
40.7315
1
35.0831
1
28.7261
1
38.049
1
36.4196
1
28.2021
1
26.1364
1
22.342
1
32.0779
1
23.8059
1
22.0759
1
18.0745
1
22.274
1
16.2103
1
18.9395
1
24.6048
1
24.849
1
23.7701
1
18.1844
1
20.1877
1
20.6776
1
19.8306
1
20.4433
1
14.0432
1
17.1597
1
25.6329
1
21.9045
1
14.1035
1
13.5584
1
20.2912
1
20.1031
1
23.4807
1
16.7521
1
12.428
1
19.6189
1
16.548
1
11.1183
1
7.61784
1
14.5042
1
13.6074
1
17.6843
1
16.5662
1
14.4561
1
16.7836
1
16.962
1
14.0811
1
14.4706
1
13.8398
1
14.036
1
17.3577
1
14.2672
1
10.8356
1
15.0913
1
12.9914
1
14.4925
1
15.2114
1
11.5549
1
17.3684
1
18.9233
1
17.2332
1
16.6
1
10.2469
1
11.4702
1
14.1106
1
12.8159
1
12.5037
1
10.2121
1
16.888
1
16.1778
1
12.0008
1
13.3756
1
15.9767
1
14.3556
1
13.922
1
12.8248
1
12.4772
1
14.5506
1
7.213
1
10.5571
1
15.5095
1
13.29
1
14.1118
1
17.6923
1
17.7448
1
12.2707
1
10.4466
1
7.7574
1
14.8916
1
12.8136
1
12.1058
1
9.56432
1
9.14188
1
11.3554
1
17.9488
1
14.9665
1
14.9954
1
13.7219
1
12.0823
1
8.50836
1
10.5378
1
9.7538
1
10.5972
1
11.4312
1
11.4147
1
14.4832
1
13.8568
1
10.9663
1
11.5206
1
8.79912
1
12.532
1
14.3405
1
14.5607
1
11.2408
1
11.2842
1
11.0903
1
14.2096
1
12.2026
1
9.77984
1
7.97444
1
6.1136
1
15.0296
1
15.2226
1
15.1302
1
14.6137
1
9.12632
1
12.5201
1
10.3713
1
14.6614
1
15.7809
1
13.0796
1
14.9818
1
15.1854
1
11.0515
1
7.08288
1
12.9523
1
8.95228
1
9.48364
1
11.5868
1
18.5096
1
12.9756
1
13.4936
1
11.3778
1
13.6265
1
14.038
1
10.6211
1
8.428
1
13.7164
1
15.4548
1
9.23428
1
11.5089
1
14.4023
1
14.8741
1
18.29
1
20.5119
1
15.5525
1
9.69364
1
15.6598
1
14.1002
1
10.0377
1
13.722
1
8.41792
1
13.724
1
12.8536
1
15.012
1
9.4192
1
13.2893
1
12.5305
1
8.79016
1
7.76244
1
20.6137
1
11.2559
1
13.0041
1
12.393
1
6.76352
1
12.337
1
12.3444
1
13.636
1
12.219
1
14.6526
1
16.2153
1
12.2086
1
14.6141
1
14.1915
1
11.428
1
11.0481
1
7.5902
1
9.81152
1
13.7343
1
17.0884
1
16.2109
1
12.9664
1
10.387
1
12.0343
1
12.608
1
13.4131
1
12.9691
1
6.1676
1
8.76976
1
16.4371
1
15.0307
1
10.9054
1
8.13444
1
9.6342
1
13.5017
1
16.091
1
19.4951
1
15.6204
1
16.6354
1
12.944
1
11.1136
1
10.0407
1
Ti 2p
O2, 1E-6 mbar O2, after 5min sputter
2030
2019
3
4
3
34
0
10
Casa Info Follows
0
0
0
0
none
Group: none
Analyzer Lens: none
Analyzer Slit: none
Scan Mode: none
XPS
0
XR 50
1486.61
0
0
0
56.5
180
FAT
20
1
4.2488
0
0
0
0
0
Ti
2p
-1
binding energy
eV
471
0.05
2
counts
d
Transmission
d
pulse counting
0.1
1
0
0
0
0
2
ESCAPE DEPTH TYPE
d
0
MFP Exponent
d
0
1002
56.6964
6586.42
1
1
117.693
1
101.169
1
99.3182
1
109.212
1
107.993
1
112.573
1
108.108
1
124.465
1
108.608
1
113.235
1
114.554
1
108.519
1
112.695
1
104.893
1
101.04
1
122.115
1
113.8
1
103.779
1
96.8834
1
97.3551
1
100.991
1
103.486
1
104.262
1
99.2687
1
106.734
1
90.0564
1
103.98
1
105.774
1
96.0308
1
80.0112
1
76.4665
1
91.4456
1
75.8386
1
83.579
1
94.1322
1
101.324
1
90.4628
1
94.3348
1
96.5957
1
96.1614
1
88.8055
1
96.819
1
92.8298
1
92.4476
1
85.47
1
86.2663
1
88.9886
1
94.993
1
92.7843
1
89.3397
1
100.948
1
74.8542
1
90.7267
1
76.1327
1
86.8594
1
93.2419
1
99.4901
1
97.397
1
83.2606
1
77.7444
1
89.0046
1
81.9128
1
78.3811
1
78.3536
1
70.2496
1
83.0229
1
76.7262
1
81.1163
1
88.3941
1
92.1507
1
89.6652
1
88.8599
1
99.1214
1
109.583
1
101.727
1
94.2785
1
74.5819
1
94.7269
1
113.489
1
103
1
91.3188
1
111.57
1
113.651
1
111.102
1
107.339
1
107.128
1
91.1641
1
105.057
1
100.298
1
108.181
1
110.191
1
119.003
1
106.172
1
127.595
1
126.393
1
125.213
1
118.971
1
141.847
1
132.794
1
128.152
1
156.595
1
123.81
1
149.427
1
149.747
1
163.75
1
158.196
1
151.916
1
171.054
1
177.535
1
169.046
1
173.525
1
188.301
1
224.329
1
213.305
1
215.963
1
234.392
1
225.244
1
217.359
1
242.918
1
253.795
1
229.868
1
235.501
1
247.603
1
262.683
1
265.918
1
255.338
1
257.052
1
258.312
1
242.012
1
238.201
1
255.028
1
257.388
1
248.669
1
243.685
1
238.661
1
247.27
1
241.924
1
233.384
1
215.522
1
223.907
1
207.74
1
207.927
1
198.372
1
181.284
1
192.408
1
188.249
1
184.003
1
183.12
1
168.591
1
164.514
1
145.817
1
139.924
1
139.829
1
148.977
1
148.292
1
121.771
1
130.808
1
137.165
1
125.074
1
119.078
1
114.079
1
119.343
1
114.023
1
114.306
1
112.406
1
105.815
1
103.273
1
109.33
1
119.057
1
92.0475
1
88.167
1
109.337
1
103.248
1
90.809
1
85.1145
1
89.0002
1
92.9078
1
91.2752
1
92.4651
1
82.9369
1
89.2195
1
88.9636
1
83.7903
1
89.1896
1
87.5043
1
108.156
1
90.0563
1
85.6123
1
87.7781
1
80.9722
1
85.9162
1
82.8144
1
88.7709
1
88.1603
1
102.812
1
96.8898
1
90.722
1
96.2354
1
88.1233
1
85.2204
1
88.2909
1
96.01
1
120.758
1
99.7612
1
96.9361
1
112.685
1
98.1636
1
103.048
1
104.209
1
111.545
1
124.612
1
128.809
1
120.433
1
119.33
1
142.321
1
128.108
1
139.393
1
158.381
1
169.219
1
181.689
1
182.537
1
188.71
1
203.269
1
219.155
1
251.616
1
274.214
1
254.424
1
282.895
1
334.731
1
368.458
1
371.576
1
403.399
1
443.022
1
437.954
1
517.442
1
555.346
1
564.494
1
585.682
1
618.15
1
627.014
1
653.422
1
641.28
1
658.642
1
645.93
1
639.186
1
636.573
1
588.688
1
565.738
1
479.787
1
463.122
1
443.427
1
427.832
1
400.675
1
352.51
1
303.049
1
286.163
1
278.643
1
242.109
1
232.759
1
193.287
1
179.974
1
150.334
1
137.821
1
132.608
1
118.971
1
110.992
1
106.158
1
93.8905
1
84.3352
1
81.305
1
83.5033
1
82.3011
1
67.1272
1
67.7632
1
59.4525
1
65.3464
1
73.3126
1
59.5664
1
52.5816
1
44.3774
1
55.4077
1
55.2852
1
62.2322
1
51.8891
1
35.8988
1
40.8678
1
35.4498
1
46.8579
1
39.5538
1
31.7387
1
30.961
1
31.0163
1
33.4642
1
27.8022
1
26.4423
1
27.0094
1
19.9268
1
19.4129
1
26.1044
1
29.9122
1
19.8517
1
26.8766
1
28.2568
1
25.9161
1
13.374
1
15.9075
1
15.1918
1
20.4507
1
16.1405
1
20.6795
1
17.7693
1
18.1509
1
18.2856
1
15.1951
1
14.0567
1
14.5201
1
18.7854
1
21.3738
1
16.1536
1
11.4618
1
12.7217
1
12.5094
1
17.3255
1
15.6043
1
11.4078
1
17.4885
1
19.8071
1
13.978
1
8.23588
1
15.9107
1
13.9312
1
13.1152
1
16.8086
1
11.8278
1
10.9743
1
19.0496
1
20.6807
1
14.1948
1
10.4005
1
14.4799
1
14.566
1
13.0005
1
17.9769
1
15.4818
1
18.5834
1
16.3474
1
10.988
1
11.9697
1
12.5595
1
15.4012
1
12.2108
1
12.4861
1
15.348
1
11.4873
1
12.5528
1
12.6156
1
18.9097
1
19.7395
1
10.4438
1
10.3944
1
10.2918
1
15.5973
1
13.4769
1
16.1859
1
6.82776
1
9.39256
1
12.9706
1
12.9972
1
8.23628
1
12.3348
1
7.68288
1
9.99784
1
12.6537
1
17.7824
1
14.1866
1
12.2244
1
13.258
1
12.7143
1
11.4785
1
12.8431
1
14.9505
1
9.18416
1
13.8546
1
16.105
1
15.6828
1
12.135
1
12.6802
1
12.762
1
16.8095
1
14.6587
1
5.66964
1
12.3107
1
12.1508
1
11.915
1
14.9198
1
17.1844
1
15.5366
1
15.6832
1
13.6382
1
16.3136
1
18.5472
1
11.5426
1
10.1702
1
9.63516
1
7.89924
1
9.88124
1
8.29136
1
12.5531
1
11.3466
1
11.7217
1
10.4556
1
13.9455
1
10.7997
1
15.0172
1
11.2578
1
16.6178
1
12.775
1
11.012
1
14.214
1
11.8035
1
11.6686
1
12.2449
1
15.072
1
13.8411
1
12.5142
1
10.3279
1
12.1576
1
12.338
1
12.5667
1
15.8963
1
15.477
1
17.5715
1
12.91
1
12.4933
1
8.26244
1
9.16272
1
7.46804
1
9.19004
1
11.259
1
10.939
1
13.6186
1
12.4502
1
13.5603
1
10.0353
1
16.2407
1
10.9486
1
9.60848
1
15.717
1
15.9758
1
11.3084
1
6.29888
1
7.21196
1
11.1758
1
15.7542
1
12.1476
1
14.6573
1
14.97
1
10.6414
1
11.6884
1
13.1173
1
9.35316
1
11.1962
1
14.5392
1
12.6158
1
14.3246
1
17.7218
1
10.7054
1
11.7134
1
16.6754
1
16.0748
1
21.5562
1
14.4552
1
12.0304
1
6.57324
1
7.15668
1
11.8618
1
6.36316
1
10.4534
1
12.1587
1
12.1373
1
12.4864
1
7.6764
1
12.5894
1
15.4974
1
14.5094
1
15.4922
1
10.2196
1
9.6772
1
9.7016
1
9.46872
1
5.98476
1
9.90812
1
13.0672
1
15.289
1
12.4294
1
8.05968
1
9.02824
1
13.798
1
11.0238
1
11.0038
1
13.5605
1
Ti 2p
O2, 1E-6 mbar O2, after 5min sputter
2030
2019
3
4
5
55
0
10
Casa Info Follows
0
0
0
0
none
Group: none
Analyzer Lens: none
Analyzer Slit: none
Scan Mode: none
XPS
0
XR 50
1486.61
0
0
0
56.5
180
FAT
20
1
4.2488
0
0
0
0
0
Ti
2p
-1
binding energy
eV
471
0.05
2
counts
d
Transmission
d
pulse counting
0.1
1
0
0
0
0
2
ESCAPE DEPTH TYPE
d
0
MFP Exponent
d
0
1002
64.0628
6914.34
1
1
124.993
1
114.969
1
121.344
1
122.64
1
116.788
1
111.623
1
102.027
1
115.16
1
122.156
1
112.78
1
110.068
1
114.941
1
98.5676
1
102.598
1
111.853
1
123.036
1
104.467
1
106.426
1
107.68
1
88.6096
1
96.5244
1
101.373
1
96.7472
1
97.7143
1
104.29
1
100.365
1
101.173
1
103.105
1
93.2037
1
86.4404
1
84.2176
1
84.3278
1
85.3412
1
89.2315
1
100.676
1
100.634
1
94.2114
1
86.3264
1
81.2538
1
86.4711
1
92.1054
1
88.0594
1
95.1809
1
98.7997
1
78.6044
1
86.3158
1
86.2676
1
91.035
1
90.2832
1
99.6926
1
92.6841
1
86.0175
1
90.0612
1
83.7561
1
81.8624
1
93.658
1
83.5954
1
81.8879
1
80.4442
1
83.568
1
89.8132
1
84.0852
1
90.9833
1
97.2421
1
94.2381
1
97.7084
1
81.4692
1
87.7166
1
85.8364
1
86.9389
1
97.7774
1
77.3472
1
97.8586
1
95.8029
1
80.1451
1
86.5444
1
86.4737
1
90.3513
1
97.3479
1
103.774
1
92.3332
1
87.6337
1
100.182
1
97.641
1
92.5596
1
95.433
1
103.843
1
118.736
1
118.136
1
119.085
1
109.929
1
115.812
1
111.516
1
109.168
1
109.719
1
110.204
1
142.278
1
134.416
1
137.594
1
147.158
1
135.423
1
160.941
1
161.643
1
151.871
1
158.362
1
170.822
1
184.287
1
185.32
1
192.996
1
185.646
1
201.511
1
184.872
1
198.562
1
205.905
1
215.426
1
232.467
1
218.078
1
232.319
1
253.721
1
253.997
1
269.764
1
213.602
1
237.367
1
251.66
1
263.825
1
258.417
1
254.565
1
257.294
1
256.858
1
254.936
1
254.595
1
266.391
1
234.01
1
259.274
1
235.546
1
232.748
1
236.56
1
243.939
1
224.592
1
203.571
1
192.285
1
202.568
1
182.601
1
180.134
1
188.157
1
192.67
1
179.621
1
173.876
1
163.406
1
144.784
1
160.022
1
143.925
1
127.883
1
140.371
1
134.761
1
125.461
1
136.764
1
118.761
1
116.888
1
113.447
1
123.054
1
120.198
1
104.704
1
114.18
1
103.498
1
94.7551
1
94.0074
1
84.0083
1
99.0874
1
103.558
1
101.449
1
103.036
1
93.1266
1
74.9403
1
87.7499
1
91.9608
1
95.5114
1
100.485
1
97.4937
1
83.9781
1
92.8671
1
96.9515
1
93.8543
1
93.4506
1
89.4706
1
88.7947
1
89.59
1
106.785
1
97.32
1
78.7205
1
83.8235
1
84.812
1
83.9025
1
101.288
1
105.96
1
111.428
1
100.065
1
93.3605
1
89.6918
1
83.4818
1
77.1101
1
101.96
1
94.6434
1
103.387
1
104.566
1
113.028
1
92.519
1
108.016
1
103.385
1
103.172
1
91.9927
1
115.513
1
135.101
1
132.513
1
111.282
1
120.617
1
160.851
1
159.537
1
162.733
1
162.069
1
184.993
1
202.947
1
170.791
1
210.375
1
246.192
1
253.152
1
277.568
1
301.291
1
345.035
1
383.784
1
395.359
1
422.324
1
427.736
1
478.941
1
531.016
1
550.02
1
600.239
1
569.621
1
577.644
1
641.785
1
636.615
1
642.235
1
691.434
1
655.242
1
612.032
1
627.332
1
550.422
1
564.634
1
522.408
1
499.656
1
463.881
1
432.661
1
389.554
1
374.902
1
322.238
1
281.906
1
256.329
1
242.175
1
209.412
1
187.722
1
208.612
1
180.062
1
147.37
1
130.202
1
120.213
1
103.016
1
87.391
1
92.2212
1
87.5494
1
86.6616
1
79.425
1
68.5279
1
66.5002
1
54.4504
1
60.2752
1
55.8348
1
56.8086
1
59.4699
1
61.1552
1
60.7008
1
56.7578
1
45.1612
1
45.0758
1
46.714
1
46.2827
1
45.7777
1
37.5761
1
33.7022
1
35.2237
1
42.9097
1
45.3621
1
35.4863
1
30.2095
1
36.6139
1
34.139
1
33.9668
1
27.6164
1
22.8206
1
16.2605
1
24.2257
1
22.1691
1
19.1068
1
26.6147
1
22.7345
1
21.6364
1
24.6276
1
19.501
1
21.3389
1
22.7687
1
20.1614
1
25.446
1
19.593
1
14.3287
1
16.9665
1
17.8996
1
17.6865
1
13.2379
1
20.9454
1
24.7125
1
15.2176
1
15.9553
1
13.1406
1
17.6068
1
19.535
1
13.7495
1
6.9848
1
12.7071
1
14.9281
1
14.3349
1
19.7988
1
17.8664
1
14.8741
1
8.82696
1
13.7642
1
18.9515
1
18.6622
1
13.1002
1
11.6188
1
14.8301
1
10.3927
1
16.477
1
14.8644
1
16.3553
1
13.9824
1
17.8698
1
16.9313
1
13.5734
1
10.9727
1
13.3973
1
13.5102
1
15.9851
1
12.3366
1
19.4094
1
12.3383
1
17.599
1
16.2132
1
13.6303
1
12.352
1
16.2031
1
17.0788
1
18.4722
1
13.7915
1
14.7158
1
12.7599
1
13.7317
1
11.4745
1
13.7301
1
13.6921
1
8.9448
1
15.8518
1
16.3492
1
11.3059
1
13.1053
1
10.7238
1
18.6217
1
19.8145
1
13.7632
1
11.9636
1
18.7022
1
15.6767
1
13.807
1
13.8417
1
9.99264
1
13.5441
1
14.6815
1
18.6401
1
10.3928
1
23.0984
1
22.1856
1
12.5744
1
19.6454
1
12.4192
1
8.88756
1
12.3876
1
15.2559
1
17.1087
1
14.1256
1
11.825
1
8.80112
1
15.7237
1
9.8006
1
11.0772
1
12.5825
1
6.99504
1
6.40628
1
10.5125
1
11.5297
1
12.0604
1
12.5709
1
12.9266
1
12.594
1
8.8764
1
10.4637
1
16.6355
1
12.1271
1
17.5624
1
15.2223
1
11.8953
1
10.5484
1
9.57096
1
15.1632
1
12.0627
1
13.949
1
12.8328
1
8.58752
1
8.91872
1
10.3723
1
12.9251
1
18.0405
1
12.2467
1
11.4954
1
12.8707
1
17.7884
1
16.3765
1
11.0357
1
12.0882
1
11.5608
1
11.4
1
12.5745
1
16.232
1
18.5713
1
16.2668
1
13.4884
1
7.86704
1
12.9298
1
13.3719
1
11.2288
1
11.3928
1
14.73
1
15.344
1
17.6226
1
17.2944
1
11.6395
1
9.466
1
13.3192
1
9.9894
1
11.144
1
14.48
1
9.303
1
15.5684
1
17.3764
1
16.4294
1
13.5268
1
11.9246
1
12.9551
1
13.971
1
11.1154
1
10.2174
1
15.3367
1
14.808
1
17.7478
1
16.2716
1
6.7372
1
8.60388
1
8.6356
1
9.9272
1
9.7632
1
8.37792
1
12.3362
1
12.9127
1
11.7359
1
11.5041
1
7.15152
1
9.68408
1
11.2611
1
[...]
187.737
1
180.796
1
182.163
1
174.964
1
177.047
1
186.25
1
170.083
1
188.065
1
180.026
1
179.977
1
191.525
1
179.471
1
182.249
1
182.239
1
199.343
1
170.992
1
182.631
1
200.666
1
198.788
1
190.697
1
201.441
1
182.497
1
203.966
1
202.358
1
212.344
1
199.284
1
184.375
1
193.516
1
203.217
1
185.877
1
203.662
1
209.924
1
187.888
1
189.19
1
207.824
1
195.398
1
189.699
1
192.393
1
204.247
1
224.098
1
192.398
1
190.343
1
199.574
1
198.41
1
199.174
1
181.729
1
183.434
1
174.721
1
190.603
1
192.219
1
191.357
1
186.847
1
187.038
1
195.393
1
176.472
1
196.042
1
181.876
1
196.741
1
196.567
1
172.295
1
180.122
1
184.762
1
176.943
1
201.788
1
204.343
1
187.106
1
169.727
1
186.641
1
193.966
1
180.744
1
213.939
1
204.399
1
191.911
1
178.633
1
182.137
1
182.324
1
199.187
1
199.291
1
186.413
1
191.67
1
185.107
1
170.408
1
195.993
1
180.079
1
170.67
1
194.615
1
188.786
1
196.938
1
197.601
1
208.418
1
220.881
1
220.359
1
201.684
1
203.891
1
226.88
1
227.336
1
214.007
1
231.324
1
240.747
1
234.219
1
243.269
1
244.607
1
234.957
1
240.089
1
244.449
1
259.416
1
276.146
1
257.794
1
263.101
1
286.967
1
288.643
1
305.429
1
302.65
1
326.864
1
309.731
1
322.092
1
328.878
1
345.721
1
323.041
1
310.037
1
318.063
1
323.938
1
328.971
1
330.502
1
318.055
1
307.091
1
311.662
1
310.52
1
321.632
1
342.99
1
310.635
1
305.29
1
315.293
1
329.221
1
296.801
1
266.51
1
294.99
1
291.175
1
292.709
1
302.369
1
274.161
1
274.341
1
264.303
1
218.014
1
243.462
1
238.543
1
245.414
1
259.653
1
274.548
1
245.774
1
247.437
1
244.664
1
241.211
1
249.288
1
235.524
1
227.079
1
230.26
1
228.794
1
237.272
1
247.928
1
225.47
1
218.554
1
214.906
1
210.898
1
209.358
1
221.802
1
225.983
1
229.618
1
236.809
1
224.985
1
224.721
1
203.971
1
197.375
1
225.496
1
197.571
1
193.569
1
189.337
1
212.055
1
188.417
1
199.676
1
198.006
1
187.548
1
196.682
1
199.531
1
182.065
1
165.128
1
168.944
1
149.205
1
156.292
1
157.05
1
160.451
1
162.139
1
154.303
1
146.695
1
161.19
1
155.484
1
140.08
1
146.352
1
145.568
1
153.466
1
156.551
1
135.625
1
144.375
1
154.503
1
153.484
1
133.553
1
150.772
1
144.219
1
167.338
1
144.27
1
140.376
1
153.524
1
163.133
1
150.912
1
159.437
1
147.54
1
151.575
1
172.582
1
162.689
1
162.333
1
151.141
1
179.897
1
179.319
1
186.681
1
179.931
1
197.479
1
219.598
1
205.911
1
226.756
1
241.724
1
254.39
1
268.859
1
272.624
1
279.522
1
300.715
1
323.517
1
340.107
1
358.493
1
339.342
1
335.651
1
370.766
1
338.32
1
323.807
1
303.315
1
290.822
1
285.252
1
254.681
1
240.91
1
225.656
1
195.145
1
153.377
1
132.056
1
129.981
1
108.838
1
80.8578
1
63.0816
1
66.7357
1
61.7367
1
55.9636
1
44.7296
1
34.2916
1
37.1
1
35.2784
1
36.2225
1
28.1078
1
29.6539
1
31.5377
1
22.4777
1
24.6933
1
32.1444
1
30.685
1
32.4968
1
26.7833
1
30.0522
1
28.2439
1
23.9789
1
21
1
31.2952
1
27.4597
1
19.3752
1
15.2162
1
18.9962
1
20.9233
1
17.884
1
20.2282
1
23.5428
1
23.2652
1
22.2396
1
19.4334
1
25.5113
1
22.6384
1
19.6944
1
22.3748
1
18.0188
1
18.7083
1
16.2284
1
16.2986
1
21.0913
1
19.3131
1
21.1222
1
22.197
1
21.8928
1
20.0262
1
22.5222
1
25.3207
1
25.6986
1
23.6483
1
22.0045
1
13.832
1
13.5282
1
22.817
1
23.2479
1
19.4894
1
22.3874
1
17.0853
1
20.0027
1
18.6192
1
16.007
1
16.4065
1
15.5164
1
18.0554
1
18.5828
1
17.933
1
13.7944
1
16.0725
1
20.9117
1
21.8349
1
16.4748
1
17.9034
1
15.184
1
16.9856
1
14.7422
1
10.3849
1
12.7255
1
17.0449
1
18.144
1
21.8174
1
18.006
1
16.9592
1
16.6965
1
15.6278
1
18.8666
1
20.6615
1
12.8145
1
10.4796
1
15.7482
1
17.6262
1
16.683
1
11.0855
1
15.6878
1
11.5315
1
13.5434
1
21.101
1
20.204
1
10.4412
1
15.2033
1
18.2917
1
12.5665
1
10.6747
1
17.622
1
22.0196
1
19.0045
1
19.483
1
19.7454
1
20.9376
1
16.0092
1
15.299
1
14.6239
1
15.4164
1
14.374
1
18.5498
1
15.0606
1
21.4295
1
19.7166
1
22.7598
1
14.3806
1
19.0988
1
20.5549
1
16.6759
1
16.4432
1
18.8747
1
24.6693
1
22.1744
1
15.8086
1
17.724
1
24.9422
1
21.8473
1
23.0918
1
12.246
1
19.0487
1
19.9093
1
20.6345
1
15.6565
1
18.0749
1
16.6837
1
15.5193
1
18.3293
1
15.241
1
15.7143
1
14.7951
1
Ti 2p
800K, O2, 5E-7 mbar O2, after reduction
2031
2019
3
11
27
1
0
10
Casa Info Follows
0
0
0
0
none
Group: none
Analyzer Lens: none
Analyzer Slit: none
Scan Mode: none
XPS
0
XR 50
1486.61
0
0
0
56.5
180
FAT
20
1
4.2488
0
0
0
0
0
Ti
2p
-1
binding energy
eV
471
0.05
2
counts
d
Transmission
d
pulse counting
0.1
1
0
0
0
0
2
ESCAPE DEPTH TYPE
d
0
MFP Exponent
d
0
1002
89.9984
3588.46
1
1
168.499
1
163.221
1
163.242
1
163.441
1
163.661
1
176.151
1
158.109
1
155.741
1
174.041
1
166.786
1
184.279
1
177.224
1
169.189
1
156.467
1
166.326
1
145.652
1
157.048
1
162.852
1
151.745
1
173.483
1
178.172
1
178.208
1
169.205
1
167.443
1
159.997
1
149.015
1
152.707
1
175.632
1
175.762
1
144.903
1
152.709
1
161.033
1
173.61
1
174.572
1
169.917
1
159.723
1
167.851
1
154.558
1
164.801
1
148.147
1
163.518
1
167.911
1
164.365
1
153.434
1
163.126
1
164.487
1
180.496
1
171.338
1
152.14
1
151.486
1
164.233
1
168.172
1
170.2
1
150.635
1
151.74
1
153.336
1
164.734
1
172.959
1
165.962
1
159.324
1
174.388
1
165.884
1
164.268
1
159.208
1
160.935
1
169.924
1
159.776
1
168.938
1
159.245
1
180.452
1
159.732
1
144.692
1
161.915
1
157.592
1
159.316
1
144.29
1
158.869
1
170.653
1
166.382
1
148.55
1
171.358
1
169.205
1
168.358
1
176.466
1
159.204
1
173.256
1
197.437
1
179.452
1
168.06
1
158.674
1
165.177
1
172.555
1
176.283
1
186.932
1
168.294
1
157.675
1
162.23
1
177.997
1
178.124
1
175.915
1
184.212
1
184.802
1
195.448
1
176.457
1
185.402
1
187.886
1
191.867
1
195.887
1
180.175
1
195.252
1
192.341
1
166.126
1
177.76
1
191.262
1
184.669
1
185.014
1
191.636
1
201.686
1
196.619
1
216.882
1
190.73
1
174.248
1
179.872
1
184.867
1
195.245
1
215.592
1
204.314
1
181.989
1
195.32
1
230.145
1
201.257
1
202.634
1
201.16
1
216.181
1
198.492
1
216.066
1
213.111
1
210.561
1
214.358
1
207.096
1
207.449
1
194.75
1
181.784
1
199.344
1
202.966
1
177.5
1
195.606
1
194.464
1
194.415
1
204.994
1
200.528
1
209.377
1
206.323
1
194.854
1
190.274
1
180.369
1
227.515
1
224.823
1
198.778
1
204.722
1
208.242
1
189.541
1
218.122
1
198.799
1
198.34
1
204.312
1
214.996
1
188.362
1
186.432
1
187.209
1
176.16
1
178.153
1
182.145
1
163.154
1
176.205
1
200.858
1
202.967
1
186.423
1
176.737
1
208.658
1
174.727
1
181.088
1
188.708
1
190.424
1
193.645
1
184.44
1
198.319
1
201.099
1
193.771
1
204.962
1
216.994
1
224.908
1
210.757
1
203.962
1
197.291
1
220.852
1
220.211
1
217.12
1
222.964
1
228.613
1
225.937
1
215.04
1
240.419
1
249.298
1
238.356
1
244.263
1
247.467
1
261.95
1
290.28
1
283.815
1
282.81
1
312.528
1
275.7
1
310.111
1
308.829
1
341.942
1
344.226
1
338.048
1
342.368
1
324.723
1
306.929
1
345.592
1
319.263
1
337.024
1
323.98
1
309.25
1
302.776
1
315.781
1
310.564
1
309.423
1
295.038
1
319.069
1
305.952
1
285.706
1
315.724
1
320.321
1
296.47
1
284.869
1
285.418
1
277.474
1
264.248
1
265.55
1
272.016
1
281.975
1
275.675
1
261.777
1
270.056
1
260.785
1
257.181
1
244.375
1
257.464
1
242.201
1
250.101
1
220.121
1
254.77
1
238.168
1
230.574
1
252.152
1
238.401
1
229.905
1
224.532
1
240.638
1
231.734
1
225.919
1
230.935
1
223.581
1
225.117
1
212.434
1
207.292
1
205.149
1
206.041
1
205.631
1
187.217
1
211.346
1
209.077
1
181.367
1
213.379
1
206.55
1
214.468
1
193.045
1
191.628
1
189.654
1
209.962
1
170.568
1
159.121
1
197.924
1
168.312
1
196.084
1
199.398
1
170.588
1
162.754
1
178.264
1
169.14
1
143.278
1
157.141
1
154.681
1
156.6
1
164.499
1
147.262
1
151.396
1
150.06
1
160.9
1
137.882
1
141.624
1
146.539
1
134.632
1
145.896
1
154.787
1
160.267
1
159.144
1
155.638
1
143.834
1
151.496
1
156.458
1
156.782
1
172.722
1
170.494
1
153.882
1
141.013
1
150.591
1
186.649
1
177.604
1
156.727
1
178.024
1
189.39
1
171.52
1
194.178
1
199.263
1
194.615
1
225.069
1
231.675
1
254.148
1
271.896
1
269.322
1
302.624
1
298.377
1
306.701
1
319.357
1
358.846
1
349.875
1
349.25
1
318.735
1
333.438
1
325.728
1
318.274
1
315.117
1
283.153
1
265.714
1
249.188
1
228.127
1
186.206
1
164.646
1
146.927
1
108.658
1
102.569
1
95.4121
1
78.7004
1
65.7179
1
66.094
1
55.0685
1
54.9298
1
39.0796
1
37.4834
1
42.4698
1
33.9239
1
44.031
1
29.0834
1
32.4514
1
29.5984
1
33.4769
1
27.2498
1
31.5296
1
25.1068
1
24.572
1
27.251
1
29.8838
1
26.6549
1
21.125
1
22.3314
1
21.6925
1
22.102
1
23.5647
1
23.6504
1
24.52
1
22.4493
1
19.342
1
18.1367
1
20.2073
1
21.8709
1
26.2335
1
30.6869
1
27.9096
1
22.5042
1
19.5878
1
21.313
1
25.586
1
19.0027
1
27.2606
1
19.5687
1
20.604
1
18.2785
1
24.5676
1
20.2952
1
18.5968
1
17.3916
1
20.7763
1
21.464
1
21.0854
1
17.6544
1
19.1534
1
20.4516
1
25.583
1
20.9164
1
14.1224
1
16.134
1
19.8596
1
22.0926
1
17.7079
1
19.665
1
20.3947
1
14.2056
1
14.422
1
21.0302
1
13.2566
1
12.0748
1
18.6297
1
18.5369
1
21.3007
1
28.651
1
17.4942
1
22.4602
1
23.832
1
15.291
1
17.3392
1
20.6742
1
21.6024
1
21.405
1
19.5262
1
16.5646
1
21.4872
1
13.9967
1
20.9978
1
18.5162
1
14.2637
1
16.7217
1
16.8157
1
22.3446
1
16.3935
1
16.0022
1
17.2749
1
20.3086
1
18.2074
1
18.2778
1
16.4235
1
22.2472
1
21.8105
1
19.8543
1
17.6267
1
11.023
1
18.5119
1
22.0176
1
23.1324
1
19.0612
1
12.6318
1
19.0125
1
20.9543
1
22.1327
1
20.9834
1
21.2706
1
17.7077
1
20.3741
1
11.2614
1
17.396
1
22.0513
1
16.4911
1
18.2723
1
19.0772
1
21.8476
1
18.4509
1
16.8025
1
19.7653
1
16.4202
1
17.9175
1
18.9729
1
12.2047
1
19.0924
1
16.1056
1
19.0946
1
20.6084
1
16.7242
1
17.327
1
16.1244
1
15.8058
1
8.99984
1
15.4354
1
17.7949
1
14.6075
1
18.0978
1
19.5954
1
23.2619
1
21.9991
1
Ti 2p
800K, O2, 5E-7 mbar O2, after reduction
2031
2019
3
11
30
16
0
10
Casa Info Follows
0
0
0
0
none
Group: none
Analyzer Lens: none
Analyzer Slit: none
Scan Mode: none
XPS
0
XR 50
1486.61
0
0
0
56.5
180
FAT
20
1
4.2488
0
0
0
0
0
Ti
2p
-1
binding energy
eV
471
0.05
2
counts
d
Transmission
d
pulse counting
0.1
1
0
0
0
0
2
ESCAPE DEPTH TYPE
d
0
MFP Exponent
d
0
1002
89.196
3447.28
1
1
150.952
1
169.821
1
175.125
1
170.392
1
162.306
1
174.164
1
165.101
1
150.231
1
147.677
1
172.179
1
171.662
1
157.206
1
151.034
1
167.219
1
151.626
1
157.204
1
158.377
1
154.281
1
169.222
1
164.203
1
160.775
1
169.363
1
178.373
1
171.562
1
170.646
1
163.732
1
179.564
1
180.684
1
174.868
1
164.382
1
142.211
1
146.794
1
161.328
1
175.777
1
159.999
1
167.193
1
159.566
1
160.653
1
160.932
1
172.239
1
165.61
1
156.52
1
161.043
1
145.127
1
150.622
1
152.547
1
162.136
1
168.882
1
167.373
1
166.815
1
151.821
1
168.451
1
165.393
1
147.664
1
159.901
1
159.789
1
149.147
1
165.311
1
161.811
1
173.952
1
157.389
1
166.523
1
157.019
1
164.861
1
162.025
1
163.334
1
170.434
1
163.751
1
169.365
1
184.623
1
148.461
1
155.123
1
142.342
1
145.911
1
165.117
1
168.298
1
169.179
1
151.679
1
163.034
1
174.136
1
160.233
1
175.117
1
170.407
1
143.755
1
168.831
1
173.612
1
160.966
1
166.991
1
171.405
1
171.115
1
172.983
1
166.178
1
152.253
1
168.019
1
181.926
1
156.018
1
166.824
1
194.329
1
182.469
1
162.857
1
176.464
1
181.417
1
179.735
1
182.686
1
169.63
1
178.171
1
174.043
1
193.016
1
179.844
1
186.237
1
183.003
1
187.359
1
176.495
1
192.894
1
199.884
1
209.292
1
177.331
1
184.632
1
196.162
1
208.294
1
190.998
1
194.895
1
197.583
1
191.522
1
171.758
1
194.512
1
193.567
1
182.386
1
192.147
1
210.605
1
210.829
1
199.243
1
199.544
1
204.282
1
218.609
1
203.124
1
201.283
1
208.766
1
198.864
1
181.787
1
187.936
1
211.888
1
205.166
1
201.847
1
206.662
1
200.483
1
210.523
1
184.269
1
191.292
1
199.682
1
204.553
1
173.763
1
183.218
1
209.149
1
197.825
1
186.252
1
188.322
1
192.523
1
181.189
1
190.042
1
195.401
1
193.611
1
182.901
1
175.836
1
194.91
1
190.651
1
191.791
1
173.688
1
177.109
1
198.641
1
193.704
1
218.655
1
207.924
1
188.604
1
186.425
1
189.431
1
168.085
1
175.48
1
166.827
1
158.535
1
173.751
1
190.307
1
197.359
1
195.057
1
179.918
1
192.658
1
215.822
1
192.314
1
181.455
1
182.917
1
187.168
1
207.618
1
203.36
1
216.434
1
221.434
1
209.771
1
195.047
1
194.351
1
232.549
1
222.945
1
201.748
1
190.404
1
219.319
1
223.612
1
235.939
1
248.16
1
273.622
1
295.073
1
263.614
1
263.959
1
286.939
1
283.253
1
287.837
1
319.125
1
340.048
1
317.05
1
338.029
1
320.624
1
299.005
1
323.778
1
329.193
1
324.13
1
326.638
1
319.602
1
312.303
1
304.546
1
327.28
1
324.078
1
326.714
1
322.361
1
313.688
1
307.73
1
291.484
1
291.28
1
295.51
1
289.489
1
260.305
1
312.559
1
275.36
1
275.599
1
321.427
1
275.024
1
263.654
1
281.628
1
252.365
1
260.901
1
286.421
1
261.411
1
274.462
1
250.217
1
223.51
1
233.298
1
239.267
1
226.545
1
236.128
1
224.295
1
229.613
1
241.645
1
208.426
1
221.723
1
211.762
1
219.246
1
216.252
1
222.081
1
221.948
1
236.156
1
231.359
1
231.756
1
210.645
1
219.621
1
197.096
1
211.651
1
224.747
1
211.687
1
241.318
1
216.233
1
208.089
1
192.307
1
205.601
1
204.256
1
188.015
1
184.283
1
186.024
1
165.001
1
159.956
1
174.416
1
167.51
1
177.444
1
182.753
1
184.385
1
176.859
1
157.878
1
171.205
1
152.521
1
153.492
1
159.854
1
157.977
1
143.52
1
147.963
1
162.461
1
131.748
1
139.928
1
120.255
1
135.034
1
156.477
1
156.695
1
140.756
1
128.734
1
129.465
1
134.852
1
144.069
1
137.813
1
130.185
1
130.082
1
146.355
1
146.545
1
142.212
1
155.364
1
147.085
1
153.911
1
149.33
1
155.175
1
158.518
1
166.982
1
174.036
1
193.036
1
188.674
1
203.644
1
197.507
1
213.889
1
240.39
1
250.655
1
241.706
1
279.372
1
276.025
1
309.557
1
336.261
1
344.728
1
304.517
1
326.422
1
341.614
1
337.921
1
339.089
1
301.963
1
290.986
1
284.031
1
252.276
1
252.47
1
225.684
1
193.931
1
171.582
1
170.774
1
137.564
1
118.589
1
111.29
1
91.4766
1
72.9577
1
71.847
1
59.444
1
53.0554
1
50.6776
1
48.197
1
49.0506
1
40.9893
1
36.3089
1
31.4495
1
36.0597
1
26.3521
1
24.913
1
28.2189
1
26.3742
1
27.6861
1
20.7724
1
26.0236
1
22.0944
1
25.8868
1
22.9467
1
23.9879
1
29.3448
1
20.8774
1
22.0623
1
23.7838
1
21.1348
1
25.6889
1
18.8095
1
22.596
1
21.7944
1
19.612
1
23.4007
1
18.4656
1
18.7124
1
21.3746
1
15.0676
1
20.0756
1
14.7418
1
15.6233
1
27.0482
1
25.9141
1
15.1139
1
19.1399
1
14.279
1
19.7355
1
19.7865
1
16.387
1
17.3911
1
19.5378
1
25.3842
1
18.5383
1
14.4148
1
21.7178
1
17.2845
1
18.727
1
24.5158
1
16.6247
1
23.474
1
22.3613
1
25.3667
1
22.8776
1
12.8381
1
19.025
1
17.9362
1
16.0708
1
8.9196
1
11.5782
1
17.6669
1
19.8141
1
24.9422
1
19.6384
1
17.5772
1
18.1292
1
14.7165
1
21.3569
1
17.7631
1
17.9013
1
19.6717
1
24.7676
1
14.8619
1
11.2869
1
22.7528
1
14.2479
1
17.0854
1
20.2161
1
19.3547
1
20.11
1
21.647
1
11.03
1
14.2385
1
14.3702
1
17.4022
1
20.1906
1
14.7296
1
13.6259
1
15.8446
1
19.3613
1
15.9328
1
17.4005
1
18.3914
1
16.2061
1
16.5887
1
14.6443
1
24.5379
1
15.9934
1
16.3733
1
15.6828
1
21.7788
1
13.3422
1
10.0558
1
14.4939
1
17.4468
1
12.3274
1
20.3272
1
16.3164
1
16.6711
1
23.4419
1
13.8573
1
15.7692
1
11.5228
1
18.8177
1
19.0799
1
20.3771
1
16.7858
1
17.4808
1
22.1102
1
19.9875
1
16.9325
1
15.2233
1
12.7627
1
16.9098
1
17.3315
1
18.2545
1
16.9086
1
18.4661
1
18.972
1
17.8744
1
16.5137
1
15.9129
1
16.3304
1
14.5603
1
16.4736
1
14.8622
1
18.9146
1
Ti 2p
800K, O2, 5E-7 mbar O2, after reduction
2031
2019
3
11
33
25
0
10
Casa Info Follows
0
0
0
0
none
Group: none
Analyzer Lens: none
Analyzer Slit: none
Scan Mode: none
XPS
0
XR 50
1486.61
0
0
0
56.5
180
FAT
20
1
4.2488
0
0
0
0
0
Ti
2p
-1
binding energy
eV
471
0.05
2
counts
d
Transmission
d
pulse counting
0.1
1
0
0
0
0
2
ESCAPE DEPTH TYPE
d
0
MFP Exponent
d
0
1002
92.5084
3403.12
1
1
177.063
1
163.252
1
173.84
1
166.798
1
159.912
1
152.572
1
167.904
1
161.082
1
157.938
1
157.157
1
159.395
1
163.46
1
167.463
1
178.648
1
144.691
1
165.552
1
166.022
1
154.457
1
148.664
1
165.993
1
162.831
1
166.873
1
165.875
1
168.639
1
167.353
1
167.681
1
160.298
1
156.936
1
139.915
1
156.965
1
142.165
1
143.17
1
138.781
1
151.601
1
139.358
1
144.599
1
164.267
1
152.463
1
145.802
1
150.649
1
150.209
1
161.628
1
166.873
1
162.47
1
150.615
1
140.13
1
156.691
1
173.942
1
153.34
1
162.664
1
141.243
1
156.803
1
152.742
1
156.486
1
162.572
1
169.583
1
152.124
1
160.053
1
145.576
1
144.451
1
157.897
1
155.292
1
149.767
1
151.656
1
170.451
1
141.878
1
148.731
1
141.877
1
152.868
1
160.83
1
164.547
1
156.761
1
161.601
1
142.869
1
147.278
1
144.2
1
140.967
1
164.032
1
173.821
1
175.228
1
153.884
1
145.353
1
145.627
1
149.614
1
164.27
1
146.77
1
167.205
1
166.409
1
165.107
1
173.162
1
187.172
1
169.18
1
166.281
1
151.695
1
172.91
1
169.927
1
183.892
1
176.575
1
167.435
1
161.704
1
157.037
1
174.81
1
181.995
1
182.795
1
200.347
1
201.991
1
209.19
1
191.868
1
200.893
1
182.94
1
193.718
1
194.205
1
210.105
1
196.895
1
190.835
1
197.384
1
201.219
1
206.375
1
183.834
1
208.372
1
186.797
1
205.107
1
202.631
1
216.912
1
218.018
1
215.389
1
214.606
1
194.963
1
214.423
1
184.434
1
200.102
1
216.416
1
215.382
1
200.589
1
203.02
1
206.502
1
195.884
1
190.743
1
200.536
1
197.147
1
210.082
1
182.206
1
202.956
1
200.662
1
179.443
1
186.157
1
197.461
1
199.579
1
172.092
1
188.694
1
185.878
1
184.463
1
189.058
1
180.47
1
192.125
1
181.424
1
198.368
1
198.289
1
179.413
1
177.194
1
187.463
1
191.184
1
179.377
1
169.797
1
177.652
1
176.04
1
174.99
1
158.822
1
177.449
1
178.997
1
177.555
1
194.328
1
179.957
1
184.867
1
192.577
1
181.019
1
180.445
1
180.399
1
197.505
1
181.471
1
182.256
1
169.032
1
190.256
1
187.719
1
179.633
1
201.112
1
192.905
1
188.261
1
182.886
1
192.823
1
199.888
1
193.917
1
190.094
1
182.104
1
178.315
1
218.589
1
202.562
1
210.415
1
218.963
1
210.541
1
216.364
1
208.743
1
233.669
1
212.011
1
262.224
1
243.136
1
227.006
1
218.336
1
242.85
1
254.342
1
268.391
1
273.89
1
289.42
1
277.181
1
278.962
1
323.14
1
315.866
1
301.988
1
321.371
1
326.41
1
330.68
1
311.578
1
329.852
1
325.67
1
315.758
1
308.272
1
340.312
1
340.101
1
334.069
1
338.551
1
322.301
1
338.535
1
318.912
1
334.016
1
315.703
1
320.394
1
331.734
1
317.045
1
329.88
1
329.446
1
328.832
1
308.019
1
287.129
1
300.913
1
309.211
1
299.81
1
305.973
1
284.223
1
268.694
1
260.232
1
267.177
1
252.508
1
253.31
1
237.367
1
247.267
1
247.253
1
225.36
1
235.571
1
228.29
1
237.373
1
242.067
1
214.905
1
226.51
1
214.677
1
210.619
1
211.213
1
205.298
1
211.655
1
202.114
1
195.756
1
178.593
1
202.595
1
189.938
1
187.987
1
201.992
1
202.562
1
187.909
1
198.682
1
194.845
1
182.118
1
182.32
1
184.261
1
185.818
1
191.352
1
178.292
1
166.997
1
159.983
1
159.055
1
155.209
1
151.12
1
156.049
1
155.313
1
148.534
1
135.09
1
142.357
1
140.384
1
140.222
1
135.295
1
131.454
1
136.838
1
138.294
1
128.278
1
132.548
1
115.767
1
130.441
1
139.055
1
131.208
1
128.004
1
123.131
1
125.558
1
121.72
1
141.258
1
134.642
1
154.246
1
144.087
1
144.36
1
146.88
1
138.145
1
140.377
1
143.045
1
149.772
1
168.706
1
172.139
1
166.214
1
176.637
1
170.46
1
187.979
1
183.6
1
207.838
1
215.211
1
224.898
1
246.467
1
260.42
1
252.753
1
288.532
1
287.093
1
308.419
1
311.239
1
317.887
1
328.806
1
329.391
1
324.828
1
295.451
1
282.804
1
295.632
1
275.178
1
235.467
1
222.381
1
209.855
1
168.295
1
167.81
1
130.952
1
117.688
1
100.681
1
84.2117
1
78.7913
1
71.4639
1
52.8459
1
49.8539
1
51.0124
1
33.2173
1
37.9182
1
36.1096
1
32.407
1
28.8168
1
30.6281
1
29.3575
1
24.6292
1
34.7878
1
31.0083
1
24.2657
1
25.2428
1
19.3219
1
32.6315
1
25.9602
1
33.203
1
29.7562
1
24.6478
1
25.5946
1
24.0916
1
18.6258
1
22.372
1
14.8046
1
17.6636
1
22.6071
1
21.4729
1
22.518
1
22.071
1
20.6667
1
25.4883
1
21.1843
1
17.6
1
17.9491
1
24.3314
1
20.5154
1
18.5503
1
22.4578
1
20.9769
1
18.9652
1
18.447
1
17.2073
1
16.3213
1
12.3237
1
18.8442
1
18.103
1
20.6045
1
18.8203
1
18.7592
1
20.1868
1
16.9333
1
17.1383
1
20.5664
1
22.6526
1
19.5878
1
25.2391
1
21.6689
1
17.9222
1
20.4073
1
24.282
1
16.3574
1
14.9298
1
18.1571
1
16.6206
1
17.5716
1
17.0515
1
27.9268
1
24.803
1
21.1778
1
17.6693
1
15.1503
1
12.2142
1
11.2024
1
17.5966
1
19.7522
1
19.9485
1
25.9716
1
17.7444
1
14.6272
1
17.6409
1
23.1412
1
16.3662
1
13.462
1
16.7893
1
21.6406
1
15.6089
1
19.8543
1
22.0523
1
13.3714
1
12.8275
1
13.106
1
19.6811
1
19.9285
1
16.4004
1
11.9955
1
15.2024
1
24.5841
1
15.3706
1
18.4173
1
18.8231
1
16.4464
1
15.0226
1
18.8346
1
17.8006
1
17.7787
1
16.8962
1
15.2905
1
17.1896
1
11.5685
1
12.5924
1
16.5672
1
14.7426
1
17.3118
1
18.7957
1
24.3415
1
17.5252
1
15.2098
1
19.4038
1
15.2985
1
13.9375
1
17.4874
1
15.2622
1
17.5611
1
11.621
1
15.7364
1
22.8722
1
18.9534
1
18.2909
1
9.25084
1
17.7592
1
15.7351
1
11.5734
1
17.9734
1
19.8299
1
17.6422
1
14.5616
1
14.4246
1
11.7126
1
16.5642
1
15.4886
1
18.0414
1
20.7273
1
end of experiment